<?xml version="1.0" ?>
<robot name="dm3">

	<link name="front_base">
		<visual>
			<geometry>
				<box size="0.24 0.10 0.05"/>
			</geometry>
			<material name="blue">
				<color rgba="0 0 .8 1"/>
			</material>
		</visual>
		<collision>
			<geometry>
				<box size="0.24 0.10 0.05"/>
			</geometry>
		</collision>
		<inertial>
			<origin rpy="0 0 0" xyz="0.000000 0.000000 0.000000"/>
			<mass value="10"/>
			<inertia ixx="0.0104" ixy="0" ixz="0" iyy="0.05638" iyz="0" izz="0.0500"/>
		</inertial>
	</link>

	<link name="front_right_wheel">
		<visual>
			<geometry>
				<cylinder length="0.02" radius="0.05"/>
			</geometry>
			<origin rpy="0 1.57075 0" xyz="0 0 0"/>
			<material name="white">
				<color rgba="1 1 1 1"/>
			</material>
		</visual>	
		<inertial>
			<origin rpy="0 0 0" xyz="0.000000 0.000000 0.000000"/>
			<mass value="0.05"/>
			<inertia ixx="0.0000329" ixy="0" ixz="0" iyy="0.0000329" iyz="0" izz="0.0000625"/>
		</inertial>
		<surface>
        <friction>
          <ode>
            <mu>200</mu>
            <mu2>150</mu2>
          </ode>
        </friction>
      </surface>
		<collision>
			<geometry>
				<cylinder length="0.02" radius="0.05"/>
			</geometry>
			<origin rpy="0 1.57075 0" xyz="0 0 0"/>
		</collision>
	</link>


	<joint name="front_base_to_right_wheel" type="continuous">
		<parent link="front_base"/>
		<child link="front_right_wheel"/>
		<origin rpy="0 0 0" xyz="0.22 0 0"/>
		<limit effort="100" velocity="100"/>
		<joint_properties damping="0.0" friction="10"/>
	</joint>

	<transmission name="front_right_wheel_tran">
		<type>transmission_interface/SimpleTransmission</type>
		<joint name="front_base_to_right_wheel">
			<hardwareInterface>VelocityJointInterface</hardwareInterface>
		</joint>
		<actuator name="front_right_wheel_motor">
		  <hardwareInterface>VelocityJointInterface</hardwareInterface>
		  <mechanicalReduction>1</mechanicalReduction>
		</actuator>
  </transmission>

	<link name="front_left_wheel">
		<visual>
			<geometry>
				<cylinder length="0.02" radius="0.05"/>
			</geometry>
			<origin rpy="0 1.57075 0" xyz="0 0 0"/>
			<material name="white">
				<color rgba="1 1 1 1"/>
			</material>
		</visual>	
		<inertial>
			<origin rpy="0 0 0" xyz="0.000000 0.000000 0.000000"/>
			<mass value="0.05"/>
			<inertia ixx="0.0000329" ixy="0" ixz="0" iyy="0.0000329" iyz="0" izz="0.0000625"/>
		</inertial>
		<surface>
        <friction>
          <ode>
            <mu>200</mu>
            <mu2>150</mu2>
          </ode>
        </friction>
      </surface>
		<collision>
			<geometry>
				<cylinder length="0.02" radius="0.05"/>
			</geometry>
			<origin rpy="0 1.57075 0" xyz="0 0 0"/>
		</collision>
	</link>


	<joint name="front_base_to_left_wheel" type="continuous">
		<parent link="front_base"/>
		<child link="front_left_wheel"/>
		<origin rpy="0 0 0" xyz="-0.22 0 0"/>
		<limit effort="100" velocity="100"/>
		<joint_properties damping="0.0" friction="10"/>
	</joint>

	<transmission name="front_left_wheel_tran">
		<type>transmission_interface/SimpleTransmission</type>
		<joint name="front_base_to_left_wheel">
			<hardwareInterface>VelocityJointInterface</hardwareInterface>
		</joint>
		<actuator name="front_left_wheel_motor">
		  <hardwareInterface>VelocityJointInterface</hardwareInterface>
		  <mechanicalReduction>1</mechanicalReduction>
		</actuator>
  </transmission>

	<link name="front_extension">
		<visual>
			<geometry>
				<box size="0.19 0.05 0.05"/>
			</geometry>
			<origin rpy="0 0 1.57075" xyz="0 -0.095 0"/>
			<material name="blue">
				<color rgba="0 0 .8 1"/>
			</material>
		</visual>
		<collision>
			<origin rpy="0 0 1.57075" xyz="0 -0.095 0"/>
			<geometry>
				<box size="0.19 0.05 0.05"/>
			</geometry>
		</collision>
		<inertial>
			<origin rpy="0 0 0" xyz="0.000000 0.000000 0.000000"/>
			<mass value="1"/>
			<inertia ixx="0.0004166" ixy="0" ixz="0" iyy="0.003216" iyz="0" izz="0.003216"/>
		</inertial>
	</link>

	<joint name="front_base_to_extension" type="fixed">
		<parent link="front_base"/>
		<child link="front_extension"/>
		<origin rpy="0 0 0" xyz="0 0 0"/>
	</joint>

	<joint name="extention_to_extension" type="continuous">
		<parent link="front_extension"/>
		<child link="back_extension"/>
		<origin rpy="0 1.57075 0" xyz="0 -.19 0"/>
		<limit effort="100" velocity="100" lower="-1" upper="1"/>
		<joint_properties damping="0.0" friction="10"/>
	</joint>

	<transmission name="extension_to_extension_tran">
		<type>transmission_interface/SimpleTransmission</type>
		<joint name="extention_to_extension">
			<hardwareInterface>EffortJointInterface</hardwareInterface>
		</joint>
		<actuator name="extension_to_extension_motor">
		  <hardwareInterface>EffortJointInterface</hardwareInterface>
		  <mechanicalReduction>1</mechanicalReduction>
		</actuator>
  </transmission>

	<link name="back_extension">
		<visual>
			<geometry>
				<box size="0.19 0.05 0.05"/>
			</geometry>
			<origin rpy="0 0 1.57075" xyz="0 -0.095 0"/>
			<material name="blue">
				<color rgba="0 0 .8 1"/>
			</material>
		</visual>
		<collision>
			<origin rpy="0 0 1.57075" xyz="0 -0.095 0"/>
			<geometry>
				<box size="0.19 0.05 0.05"/>
			</geometry>
		</collision>
		<inertial>
			<origin rpy="0 0 0" xyz="0.000000 0.000000 0.000000"/>
			<mass value="0.0001"/>
			<inertia ixx="1e-08" ixy="0" ixz="0" iyy="1e-08" iyz="0" izz="1e-08"/>
		</inertial>
	</link>

	<link name="back_base">
		<visual>
			<geometry>
				<box size="0.24 0.10 0.05"/>
			</geometry>
			<material name="blue">
				<color rgba="0 0 .8 1"/>
			</material>
		</visual>
		<collision>
			<geometry>
				<box size="0.24 0.10 0.05"/>
			</geometry>
		</collision>
		<inertial>
			<origin rpy="0 0 0" xyz="0.000000 0.000000 0.000000"/>
			<mass value="10"/>
			<inertia ixx="0.0104" ixy="0" ixz="0" iyy="0.05638" iyz="0" izz="0.0500"/>
		</inertial>
	</link>

	<joint name="back_base_to_extension" type="fixed">
		<parent link="back_extension"/>
		<child link="back_base"/>
		<origin rpy="0 -1.57075 0" xyz="0 -0.19 0"/>
	</joint>

	<link name="back_right_wheel">
		<visual>
			<geometry>
				<cylinder length="0.02" radius="0.05"/>
			</geometry>
			<origin rpy="0 1.57075 0" xyz="0 0 0"/>
			<material name="white">
				<color rgba="1 1 1 1"/>
			</material>
		</visual>
		<inertial>
			<origin rpy="0 0 0" xyz="0.000000 0.000000 0.000000"/>
			<mass value="0.05"/>
			<inertia ixx="0.0000329" ixy="0" ixz="0" iyy="0.0000329" iyz="0" izz="0.0000625"/>
		</inertial>
		<surface>
        <friction>
          <ode>
            <mu>200</mu>
            <mu2>150</mu2>
          </ode>
        </friction>
      </surface>
		<collision>
			<geometry>
				<cylinder length="0.02" radius="0.05"/>
			</geometry>
			<origin rpy="0 1.57075 0" xyz="0 0 0"/>
		</collision>
	</link>


	<joint name="back_base_to_right_wheel" type="continuous">
		<parent link="back_base"/>
		<child link="back_right_wheel"/>
		<origin rpy="0 0 0" xyz="0.22 0 0"/>
		<limit effort="100" velocity="100"/>
		<joint_properties damping="0.0" friction="10"/>
	</joint>

	<transmission name="back_right_wheel_tran">
		<type>transmission_interface/SimpleTransmission</type>
		<joint name="back_base_to_right_wheel">
			<hardwareInterface>VelocityJointInterface</hardwareInterface>
		</joint>
		<actuator name="back_right_wheel_motor">
		  <hardwareInterface>VelocityJointInterface</hardwareInterface>
		  <mechanicalReduction>1</mechanicalReduction>
		</actuator>
  </transmission>

	<link name="back_left_wheel">
		<visual>
			<geometry>
				<cylinder length="0.02" radius="0.05"/>
			</geometry>
			<origin rpy="0 1.57075 0" xyz="0 0 0"/>
			<material name="white">
				<color rgba="1 1 1 1"/>
			</material>
		</visual>
		<surface>
        <friction>
          <ode>
            <mu>200</mu>
            <mu2>150</mu2>
          </ode>
        </friction>
      </surface>
		<inertial>
			<origin rpy="0 0 0" xyz="0.000000 0.000000 0.000000"/>
			<mass value="0.05"/>
			<inertia ixx="0.0000329" ixy="0" ixz="0" iyy="0.0000329" iyz="0" izz="0.0000625"/>
		</inertial>
		<collision>
			<geometry>
				<cylinder length="0.02" radius="0.05"/>
			</geometry>
			<origin rpy="0 1.57075 0" xyz="0 0 0"/>
		</collision>
	</link>


	<joint name="back_base_to_left_wheel" type="continuous">
		<parent link="back_base"/>
		<child link="back_left_wheel"/>
		<origin rpy="0 0 0" xyz="-0.22 0 0"/>
		<limit effort="100" velocity="100"/>
		<joint_properties damping="0.0" friction="10"/>
	</joint>
	<transmission name="back_left_wheel_tran">
		<type>transmission_interface/SimpleTransmission</type>
		<joint name="back_base_to_left_wheel">
			<hardwareInterface>VelocityJointInterface</hardwareInterface>
		</joint>
		<actuator name="back_left_wheel_motor">
		  <hardwareInterface>VelocityJointInterface</hardwareInterface>
		  <mechanicalReduction>1</mechanicalReduction>
		</actuator>
  </transmission>
	

	<gazebo>
	  <plugin name="gazebo_ros_control" filename="libgazebo_ros_control.so">
	    <robotNamespace>/myrobot</robotNamespace>
	  </plugin>
	</gazebo>
</robot>


